<?xml version="1.0"?>
<robot name="moveable_robot">
  <link name="base_link">
     <visual>
        <geometry>
            <box size="0.4 0.4 0.2"/>
        </geometry>
        <material name="blue">
            <color rgba="0 0 .8 1"/>
        </material>
     </visual>
  </link>

  <link name="link_1">
     <visual>
        <geometry>
         <box size="0.1 0.1 0.2" />
        </geometry>
        <origin xyz="0 0 0.1"/>       
     </visual>
  </link>

  <link name="link_2">
     <visual>
        <geometry>
         <box size="0.4 0.1 0.1" />
        </geometry>
        <origin xyz="0.2 0 0"/>       
     </visual>
  </link>

  <link name="link_3">
     <visual>
        <geometry>
         <box size="0.2 0.1 0.1" />
        </geometry>
	<material name="white">
            <color rgba="1 1 1 1"/>
        </material>
        <origin xyz="0.1 0 0"/>       
     </visual>
  </link>

  <joint name="base_to_link_1" type="continuous">

    <parent link="base_link"/>
    <child link="link_1"/>
    <origin xyz="0 0 0.1" rpy="0 0 0"/>
    <axis xyz="0 0 1"/>
  </joint>

  <joint name="link_1_to_link_2" type="revolute">
    <parent link="link_1"/>
    <child link="link_2"/>
    <origin xyz="0 0 0.2" rpy="-1.57 0 0"/>
    <axis xyz="0 0 1"/>
	<limit effort="1000.0" lower="-1.57" upper="0.5" velocity="0.5"/>
  </joint>

  <joint name="link_2_to_link_3" type="revolute">
    <parent link="link_2"/>
    <child link="link_3"/>
    <origin xyz="0.4 0 0" rpy="0 0 0"/>
    <axis xyz="0 0 1"/>
	<limit effort="1000.0" lower="-1.57" upper="1.57" velocity="0.5"/>
  </joint>

</robot>
